---
layout: post
date: 2021-03-09 21:19:16 -TTTT
title: '[Node.js] Mysql2 모듈 사용하여 장시간 켜놓을시 커넥션 예외가 발생하는 이슈'
description: Mysql2 모듈 사용하여 장시간 켜놓을시 커넥션 예외가 발생하는 이슈
tags: 
- mysql2 
- mysql
- nodejs
categories:
comments: true
---
최근 기존 시스템의 `DB Connection pool` 관련 서버코드를 변경하였는데   
이후 몇일 뒤 로컬 환경에서 서버를 켜두고 퇴근을 하고 난 다음날 중지하지 않았던 서버에 `request`를 요청시 이따금 이상한 오류가 발생하였다.

### 발생오류
```
1. Error: Can't add new command when connection is in closed state

2. Error: This socket has been ended by the other party
```

이상하게도 이번에 변경한 코드내에서는 처리한 부분이 `connection`을 `release(반납)` 위치만 바꾸었을뿐인데
특별히 발생할 오류는 아닌것 같았다.

에러 내용을 보면  
- 커넥션이 닫힌상테에서는 새로운 명령을 추가 할 수 없다.
- 이 소켓은 상대측에 의해 종료되었다.
  
인데 도통 감이 오지 않았다. 

괜스레 적용한 코드가 잘 못 되었나 하고 되짚어 보았지만 마땅히 짚히는 구석이 보이진 않았다.

### [mysql2](https://github.com/sidorares/node-mysql2) 
우선적으로 생각해보니 이전에 내가 개발하고 운영했던 서비스 서버를 생각해보니 당시에는 nodejs에 mysqljs 모듈을 사용하였고 현재는 mysql2를 사용하고 있다.
  
`mysql2`가 가진 기존 `mysqljs`와의 차이점으로는 크게 

- 더 빠르고 더 나은 성능
- promise 지원 

가 있고 `mysql2`의 소개페이지에도 나와 있는데 대부분의 mysqljs 기능을 지원하고 있다고 한다.   
(이외에 기능은 사실 mysqljs 기반으로 추가하여 가능한 부분이라서 잘 와닿지가 ㅎ promise도 마찬가지지만. )

특별히 이점이 문제가 될 것처럼 보이지는 않았다.

### 구글링
일단 오류내용을 google, git issue 페이지에서 찾았다.

[node-mysql2: Issues#939](https://github.com/sidorares/node-mysql2/issues/939)  

이슈 내용을 보면 굉장히 많은 다른 사용자들이 동일 현상을 겪고 있었고 해결이 되지 않은것 처럼 확인된것으로 보였다.
  
몇몇은 `connection` 방식에서 `connection pool` 방식으로 변경하여 해결이 되었다고 하지만 현재 시스템에서는 이미 `connection pool`을 사용하고 있었기에 
해결방안이 되지 않았다.

또한 해당 개발자가 재현도 안된다고..

[**mysql2 개발자 sidorares의 comment**]  

> [sidorares commented on 7 Apr 2020]  
> unfortunately not enough information to debug. Can you make a test repo to reproduce?
This can happen if you call .end() on connection and later try to call .execute() this might be a logic error in your application but could be a bug in the driver, unfortunately not enough information to tell


또한 두번째 `Error: This socket has been ended by the other party` 의 경우는 특이하게 mysql2 에서 많이 발생하였고
mysql2 를 기반으로 사용하는 orm 모듈에서도 발생사례가 제보된것이 확인되었다.

하지만 이렇다할 해결 방안이나 fix된 내용도 확인되지 않았다.

### 재현
대부분의 경우가 (내 상황과 마찬가지로) 장기간 실행시 idle 상태로 방치하고 연결이 없을때 주로 발생 되는 것으로 확인되었는데
몇가지 재현 스택에 가닥이 잡혀 시도 해보았다.

1. `MYSQL` 서버 `wait_timeout` 값 변경하여 `connection` 테스트 
    - `mysql` 서버내에 `wait_timeout` 설정을 10~20초로 변경.
    - 서버에 `request`를 요청하여 `pool` 내에 `connection` 을 생성/유지 
    - `connection`이 `wait_timeout` 설정을 넘겼을때 오류가 발생하는지?  
     
2. `mysql` 서버에서 `nodejs` 서버에서 맺고있는 thread를 kill     
3. `nodejs` 서버 또는 `mysql` 서버측간에 네트워크 강제로 끊기

1, 2, 3의 모든 경우에도 `request` 요청시 connection 관련 오류가 발생하지 않았다.

#### 코드 확인
도통 재현이 되지 않으니 찜찜함이 너무 남아서 기존 mysql2 모듈 파일을 확인하고 대략적인 흐름으로 확인해보았다.  

```
  _addCommandClosedState(cmd) {
    // 오류 발생지점
    const err = new Error(
      "Can't add new command when connection is in closed state"
    );
    err.fatal = true;
    if (cmd.onResult) {
      cmd.onResult(err);
    } else {
      this.emit('error', err);
    }
  }
  
  // handleFatal 오류 
  _handleFatalError(err) {
    err.fatal = true;
    // stop receiving packets
    this.stream.removeAllListeners('data');
    this.addCommand = this._addCommandClosedState;
    this.write = () => {
      this.emit('error', new Error("Can't write in closed state"));
    };
    this._notifyError(err);
    this._fatalError = err;
  }

  // handle Network error로 부터 던져졌을것 같음.
  _handleNetworkError(err) {
    if (this.connectTimeout) {
      Timers.clearTimeout(this.connectTimeout);
      this.connectTimeout = null;
    }
    // Do not throw an error when a connection ends with a RST,ACK packet
    if (err.errno === 'ECONNRESET' && this._closing) {
      return;
    }
    this._handleFatalError(err);
  }
```

## 조치 (해결이라 쓰면 좋겠으나)
이전 시스템에서 release(반납) 로직이 잘못되어 pool에서 connection을 여러개를 사용하지 못하고 대기하는 현상을 수정한것인데 
이번에 release 관련 로직을 수정함으로 유휴 connection이 발생하여 해당 connection 사용시 오류가 발생한것으로 예상되었다.
  
또 결정적으로 mysql과 mysql2는 다시 가져온 connection 자체가 유효한지 체크 로직 유무가 다르다고 한다.(validate관련 한 로직이 mysql2에는 없다고 함, 정확하지 않음.)

확실하지는 않지만 pool에서 가져온 connection 자체가 문제가 있다면 pool에 반환하지 않고 destroy 시키고 다시 connection을 가져오는 
방향으로 로직을 수정하였다. 

```
// <구현 예>
// * 이전 시스템은 async await을 특별히 사용하지 않은 callback방식
// 변경전 
function getConnection(pool, callback) {
    pool.getConnection(function(err, connection) {
        if(err) {
            console.log("getRetryConnection err : " + err);
            // connection 종료처리
            connection.destroy();
            callback(err);
        }
        else {
            callback(null, connection);
        }
    })
}

// 변경후
function getConnection(pool, callback) {
    pool.getConnection(function(err, connection) {
        if(err) {
            console.log("getRetryConnection err : " + err);
            // connection 종료처리
            connection.destroy();

            // 재연결 처리를 1회 다시한번 진행.
            pool.getConnection(function(reConnErr, reConnection) {
                // 재연결시에도 오류가 발생하면 커넥션 파괴 후 error 콜백 반환
                if(reConnErr) {
                    console.log("getRetryConnection retry fail err : " + err);
                    reConnection.destroy();
                    return callback(reConnErr);
                }
                callback(reConnErr, reConnection);
            });
        }
        else {
            callback(null, connection);
        }
    })
}


```
조금 더 나은 방식이라면 재귀나 참조를 통해 적당한 선에서 n회차 반복처리를 하였으나 장기간 비활성시 종료되었을때라서 1회만 다시 시도해도 문제 없을것 같아 위 같이 처리하였다. 

일단은 앞서 발생한 오류가 발생해도 재연결 처리를 하니 문제는 없겠지만... 재현도 안되는데 수정부터 하니 굉장히 마음이 찜찜하다.  (내 로컬 PC에서 발생한 것도 아니어서)
 
추후 더 나은 방향이 있거나 해결방안이 있으면 수정해야지.

 
  
 




 




